<mujoco model="h1_2">
  <compiler angle="radian" meshdir="../meshes/" eulerseq="zyx"/>
  <option timestep='0.001' iterations='50' solver='PGS' gravity='0 0 -9.81'>
    <!-- <flag sensornoise="enable" frictionloss="enable"/> -->
  </option>
  <size njmax="500" nconmax="100" />

  <visual>
    <quality shadowsize='4096'/>
    <map znear='0.05'/>
  </visual>

  <default>
    <joint limited='true' damping="0.1"/>
    <motor ctrllimited='true'/>
    <geom condim='4' contype="1" conaffinity="15" solref='0.001 2' friction='0.90 0.9 0.9'/>
    <equality solref='0.001 2'/>
    <default class='visualgeom'>
      <geom material='visualgeom' condim='1' contype='0' conaffinity='0'/>
    </default>
    <default class='visualgeom2'>
      <geom material='visualgeom2' condim='1' contype='0' conaffinity='0'/>
    </default>
    <default class='obstacle'>
      <geom material='obstacle' condim='3' contype='1' conaffinity='15'/>
    </default>
  </default>
  <asset>
    <texture type="skybox" builtin="gradient" rgb1="0.3 0.5 0.7" rgb2="0 0 0" width="512" height="512"/>
    <texture name="texplane" type="2d" builtin="checker" rgb1=".2 .3 .4" rgb2=".1 0.15 0.2" width="512" height="512" mark="cross" markrgb=".8 .8 .8"/>
    <texture name="texplane2" type="2d" builtin="checker" rgb1="1 0.3137 0.1843" rgb2="0.0 0.30196 0.38039" width="512" height="512" mark="cross" markrgb=".8 .8 .8"/>

    <material name="matplane" reflectance="0." texture="texplane" texrepeat="1 1" texuniform="true"/>
    <material name="matplane2" reflectance="0.1" texture="texplane2" texrepeat="1 1" texuniform="true"/>

    <material name='obstacle' rgba='0.9 0.6 0.2 1'/>
    <material name='visualgeom' rgba='0.5 0.9 0.2 1'/>
    <material name='visualgeom2' rgba='0.5 0.9 0.2 1'/>

    <mesh name="pelvis" file="pelvis.STL"/>
    <mesh name="left_hip_yaw_link" file="left_hip_yaw_link.STL"/>
    <mesh name="left_hip_pitch_link" file="left_hip_pitch_link.STL"/>
    <mesh name="left_hip_roll_link" file="left_hip_roll_link.STL"/>
    <mesh name="left_knee_link" file="left_knee_link.STL"/>
    <mesh name="left_ankle_pitch_link" file="left_ankle_pitch_link.STL"/>
    <mesh name="left_ankle_roll_link" file="left_ankle_roll_link.STL"/>
    <mesh name="right_hip_yaw_link" file="right_hip_yaw_link.STL"/>
    <mesh name="right_hip_pitch_link" file="right_hip_pitch_link.STL"/>
    <mesh name="right_hip_roll_link" file="right_hip_roll_link.STL"/>
    <mesh name="right_knee_link" file="right_knee_link.STL"/>
    <mesh name="right_ankle_pitch_link" file="right_ankle_pitch_link.STL"/>
    <mesh name="right_ankle_roll_link" file="right_ankle_roll_link.STL"/>
    <mesh name="torso_link" file="torso_link.STL"/>
    <mesh name="left_shoulder_pitch_link" file="left_shoulder_pitch_link.STL"/>
    <mesh name="left_shoulder_roll_link" file="left_shoulder_roll_link.STL"/>
    <mesh name="left_shoulder_yaw_link" file="left_shoulder_yaw_link.STL"/>
    <mesh name="left_elbow_link" file="left_elbow_link.STL"/>
    <mesh name="left_wrist_roll_link" file="left_wrist_roll_link.STL"/>
    <mesh name="left_wrist_pitch_link" file="left_wrist_pitch_link.STL"/>
    <mesh name="wrist_yaw_link" file="wrist_yaw_link.STL"/>
    <mesh name="right_shoulder_pitch_link" file="right_shoulder_pitch_link.STL"/>
    <mesh name="right_shoulder_roll_link" file="right_shoulder_roll_link.STL"/>
    <mesh name="right_shoulder_yaw_link" file="right_shoulder_yaw_link.STL"/>
    <mesh name="right_elbow_link" file="right_elbow_link.STL"/>
    <mesh name="right_wrist_roll_link" file="right_wrist_roll_link.STL"/>
    <mesh name="right_wrist_pitch_link" file="right_wrist_pitch_link.STL"/>
    <mesh name="logo_link" file="logo_link.STL"/>
    <mesh name="L_hand_base_link" file="L_hand_base_link.STL"/>
    <mesh name="link11_L" file="link11_L.STL"/>
    <mesh name="link12_L" file="link12_L.STL"/>
    <mesh name="link13_L" file="link13_L.STL"/>
    <mesh name="link14_L" file="link14_L.STL"/>
    <mesh name="link15_L" file="link15_L.STL"/>
    <mesh name="link16_L" file="link16_L.STL"/>
    <mesh name="link17_L" file="link17_L.STL"/>
    <mesh name="link18_L" file="link18_L.STL"/>
    <mesh name="link19_L" file="link19_L.STL"/>
    <mesh name="link20_L" file="link20_L.STL"/>
    <mesh name="link21_L" file="link21_L.STL"/>
    <mesh name="link22_L" file="link22_L.STL"/>
    <mesh name="R_hand_base_link" file="R_hand_base_link.STL"/>
    <mesh name="link11_R" file="link11_R.STL"/>
    <mesh name="link12_R" file="link12_R.STL"/>
    <mesh name="link13_R" file="link13_R.STL"/>
    <mesh name="link14_R" file="link14_R.STL"/>
    <mesh name="link15_R" file="link15_R.STL"/>
    <mesh name="link16_R" file="link16_R.STL"/>
    <mesh name="link17_R" file="link17_R.STL"/>
    <mesh name="link18_R" file="link18_R.STL"/>
    <mesh name="link19_R" file="link19_R.STL"/>
    <mesh name="link20_R" file="link20_R.STL"/>
    <mesh name="link21_R" file="link21_R.STL"/>
    <mesh name="link22_R" file="link22_R.STL"/>

    <hfield name='hf0' nrow='200' ncol='200' size="10 5 0.2 .1"/>
  </asset>
  <worldbody>
    <light directional="true" diffuse=".4 .4 .4" specular="0.1 0.1 0.1" pos="0 0 5.0" dir="0 0 -1" castshadow="false"/>
    <light directional="true" diffuse=".6 .6 .6" specular="0.2 0.2 0.2" pos="0 0 4" dir="0 0 -1"/>
    <geom name="ground" type="plane" size="0 0 1" pos="0.001 0 0" quat="1 0 0 0" material="matplane" condim="1" conaffinity='15'/>

    <body name="pelvis" pos="0 0 1.0255">
      <inertial pos="-0.0004 3.7e-05 -0.046864" quat="0.497097 0.496809 -0.503132 0.502925" mass="5.983" diaginertia="0.0531565 0.0491678 0.00902583"/>
      <joint name="floating_base_joint" type="free" limited="false"/>

      <!-- <joint type='slide' axis='1 0 0' limited='false' />
      <joint type='slide' axis='0 1 0' limited='false' /> -->
      <!-- <joint type='slide' axis='0 0 1' limited='false' />
      <joint type='ball' limited='false' /> -->


      <geom type="mesh" contype="0" conaffinity="0" group="1" density="0" rgba="0.4 1 1 1" mesh="pelvis"/>
      <geom size="0.05" rgba="0.4 1 1 1"/>
      <geom type="mesh" contype="0" conaffinity="0" group="1" density="0" rgba="0.4 1 1 1" mesh="torso_link"/>
      <geom size="0.04 0.08 0.05" pos="0 0 0.15" type="box" rgba="0.4 1 1 1"/>
      <geom pos="0 0.14806 0.42333" quat="0.991445 0.130526 0 0" type="mesh" contype="0" conaffinity="0" group="1" density="0" rgba="0.4 1 1 1" mesh="left_shoulder_pitch_link"/>
      <geom size="0.005 0.005 0.005" pos="0 0.14806 0.42333" quat="0.991445 0.130526 0 0" type="box" rgba="0.4 1 1 1"/>
      <geom pos="0.0342 0.2095 0.43358" type="mesh" contype="0" conaffinity="0" group="1" density="0" rgba="0.4 1 1 1" mesh="left_shoulder_roll_link"/>
      <geom size="0.005 0.005 0.005" pos="0.0342 0.2095 0.43358" type="box" rgba="0.4 1 1 1"/>
      <geom pos="0 0.2095 0.28798" type="mesh" contype="0" conaffinity="0" group="1" density="0" rgba="0.4 1 1 1" mesh="left_shoulder_yaw_link"/>
      <geom size="0.005 0.005 0.005" pos="0 0.2095 0.28798" type="box" rgba="0.4 1 1 1"/>
      <geom pos="0.006 0.2424 0.10598" type="mesh" contype="0" conaffinity="0" group="1" density="0" rgba="0.4 1 1 1" mesh="left_elbow_link"/>
      <geom size="0.005 0.005 0.005" pos="0.006 0.2424 0.10598" type="box" rgba="0.4 1 1 1"/>
      <geom pos="0.127 0.2095 0.0949799" type="mesh" contype="0" conaffinity="0" group="1" density="0" rgba="0.4 1 1 1" mesh="left_wrist_roll_link"/>
      <geom size="0.005 0.005 0.005" pos="0.127 0.2095 0.0949799" type="box" rgba="0.4 1 1 1"/>
      <geom pos="0.214 0.2095 0.0949799" type="mesh" contype="0" conaffinity="0" group="1" density="0" rgba="0.4 1 1 1" mesh="left_wrist_pitch_link"/>
      <geom size="0.005 0.005 0.005" pos="0.214 0.2095 0.0949799" type="box" rgba="0.4 1 1 1"/>
      <geom pos="0.234 0.2095 0.0949799" type="mesh" contype="0" conaffinity="0" group="1" density="0" rgba="0.4 1 1 1" mesh="wrist_yaw_link"/>
      <geom size="0.005 0.005 0.005" pos="0.234 0.2095 0.0949799" type="box" rgba="0.4 1 1 1"/>
      <geom pos="0 -0.14806 0.42333" quat="0.991445 -0.130526 0 0" type="mesh" contype="0" conaffinity="0" group="1" density="0" rgba="0.4 1 1 1" mesh="right_shoulder_pitch_link"/>
      <geom size="0.005 0.005 0.005" pos="0 -0.14806 0.42333" quat="0.991445 -0.130526 0 0" type="box" rgba="0.4 1 1 1"/>
      <geom pos="0.0342 -0.2095 0.43358" type="mesh" contype="0" conaffinity="0" group="1" density="0" rgba="0.4 1 1 1" mesh="right_shoulder_roll_link"/>
      <geom size="0.005 0.005 0.005" pos="0.0342 -0.2095 0.43358" type="box" rgba="0.4 1 1 1"/>
      <geom pos="0 -0.2095 0.28798" type="mesh" contype="0" conaffinity="0" group="1" density="0" rgba="0.4 1 1 1" mesh="right_shoulder_yaw_link"/>
      <geom size="0.005 0.005 0.005" pos="0 -0.2095 0.28798" type="box" rgba="0.4 1 1 1"/>
      <geom pos="0.006 -0.2424 0.10598" type="mesh" contype="0" conaffinity="0" group="1" density="0" rgba="0.4 1 1 1" mesh="right_elbow_link"/>
      <geom size="0.005 0.005 0.005" pos="0.006 -0.2424 0.10598" type="box" rgba="0.4 1 1 1"/>
      <geom pos="0.127 -0.2095 0.0949799" type="mesh" contype="0" conaffinity="0" group="1" density="0" rgba="0.4 1 1 1" mesh="right_wrist_roll_link"/>
      <geom size="0.005 0.005 0.005" pos="0.127 -0.2095 0.0949799" type="box" rgba="0.4 1 1 1"/>
      <geom pos="0.214 -0.2095 0.0949799" type="mesh" contype="0" conaffinity="0" group="1" density="0" rgba="0.4 1 1 1" mesh="right_wrist_pitch_link"/>
      <geom size="0.005 0.005 0.005" pos="0.214 -0.2095 0.0949799" type="box" rgba="0.4 1 1 1"/>
      <geom pos="0.234 -0.2095 0.0949799" type="mesh" contype="0" conaffinity="0" group="1" density="0" rgba="0.4 1 1 1" mesh="wrist_yaw_link"/>
      <geom size="0.005 0.005 0.005" pos="0.234 -0.2095 0.0949799" type="box" rgba="0.4 1 1 1"/>
      <geom type="mesh" contype="0" conaffinity="0" group="1" density="0" rgba="1 1 1 1" mesh="logo_link"/>
      <body name="left_hip_yaw_link" pos="0 0.0875 -0.1632" gravcomp="0">
        <inertial pos="0 -0.026197 0.006647" quat="0.704899 -0.0553755 0.0548434 0.705013" mass="2.829" diaginertia="0.00574303 0.00455361 0.00349461"/>
        <joint name="left_hip_yaw_joint" pos="0 0 0" axis="0 0 1" range="-0.43 0.43"/>
        <geom type="mesh" contype="0" conaffinity="0" group="1" density="0" rgba="0.4 1 1 1" mesh="left_hip_yaw_link"/>
        <geom size="0.01 0.01" pos="0.02 0 0" quat="0.707107 0 0.707107 0" type="cylinder" rgba="0.4 1 1 1"/>
        <body name="left_hip_pitch_link" pos="0 0.0755 0" quat="0.99875 0 -0.0499792 0" gravcomp="0">
          <inertial pos="-0.00781 -0.004724 -6.3e-05" quat="0.701575 0.711394 0.0330266 0.0249149" mass="2.92" diaginertia="0.00560661 0.00445055 0.00385068"/>
          <joint name="left_hip_pitch_joint" pos="0 0 0" axis="0 1 0" range="-1.8 1.7"/>
          <geom type="mesh" contype="0" conaffinity="0" group="1" density="0" rgba="0.4 1 1 1" mesh="left_hip_pitch_link"/>
          <geom size="0.02 0.01" pos="0 0.06 0" quat="0.707388 0.706825 0 0" type="cylinder" rgba="0.4 1 1 1"/>
          <body name="left_hip_roll_link" pos="0 0 0" gravcomp="0">
            <inertial pos="0.004171 -0.008576 -0.194509" quat="0.634842 0.0146079 0.0074063 0.772469" mass="4.962" diaginertia="0.0480229 0.0462788 0.00887409"/>
            <joint name="left_hip_roll_joint" pos="0 0 0" axis="1 0 0" range="-0.43 3.14"/>
            <geom type="mesh" contype="0" conaffinity="0" group="1" density="0" rgba="0.4 1 1 1" mesh="left_hip_roll_link"/>
            <geom size="0.02 0.1" pos="0 0 -0.2" type="cylinder" rgba="0.4 1 1 1"/>
            <body name="left_knee_link" pos="0 0 -0.4" quat="0.995004 0 0.0998334 0" gravcomp="0">
              <inertial pos="0.000179 0.000121 -0.168936" quat="0.416585 0.0104983 0.00514003 0.909021" mass="3.839" diaginertia="0.0391044 0.038959 0.00501125"/>
              <joint name="left_knee_joint" pos="0 0 0" axis="0 1 0" range="-0.32 1.99"/>
              <geom type="mesh" contype="0" conaffinity="0" group="1" density="0" rgba="0.4 1 1 1" mesh="left_knee_link"/>
              <geom size="0.02 0.1" pos="0 0 -0.2" type="cylinder" rgba="0.4 1 1 1"/>
              <body name="left_ankle_pitch_link" pos="0 0 -0.4" quat="0.99875 0 -0.0499792 0" gravcomp="0">
                <inertial pos="-0.000294 0 -0.010794" quat="0.999984 0 -0.00574445 0" mass="0.102" diaginertia="2.39454e-05 2.1837e-05 1.34126e-05"/>
                <joint name="left_ankle_pitch_joint" pos="0 0 0" axis="0 1 0" range="-0.797334 0.623598"/>
                <geom type="mesh" contype="0" conaffinity="0" group="1" density="0" rgba="0.4 1 1 1" mesh="left_ankle_pitch_link"/>
                <geom type="mesh" rgba="0.4 1 1 1" mesh="left_ankle_pitch_link"/>
                <body name="left_ankle_roll_link" pos="0 0 -0.02" gravcomp="0">
                  <inertial pos="0.029589 0 -0.015973" quat="0 0.725858 0 0.687845" mass="0.747" diaginertia="0.00359178 0.00343534 0.000640307"/>
                  <joint name="left_ankle_roll_joint" pos="0 0 0" axis="1 0 0" range="-0.261799 0.261799"/>
                  <geom type="mesh" contype="0" conaffinity="15" group="1" density="0" rgba="0.4 1 1 1" mesh="left_ankle_roll_link"/>
                  <geom size="0.005" pos="-0.08 0.038 -0.041" rgba="0.4 1 1 1"/>
                  <geom size="0.005" pos="-0.08 -0.038 -0.041" rgba="0.4 1 1 1"/>
                  <geom size="0.005" pos="-0.06 0.038 -0.041" rgba="0.4 1 1 1"/>
                  <geom size="0.005" pos="-0.06 -0.038 -0.041" rgba="0.4 1 1 1"/>
                  <geom size="0.005" pos="0.135 0.038 -0.041" rgba="0.4 1 1 1"/>
                  <geom size="0.005" pos="0.135 -0.038 -0.041" rgba="0.4 1 1 1"/>
                  <geom size="0.005" pos="0.095 0.038 -0.041" rgba="0.4 1 1 1"/>
                  <geom size="0.005" pos="0.095 -0.038 -0.041" rgba="0.4 1 1 1"/>
                  <geom size="0.005" pos="0.17 0.02 -0.041" rgba="0.4 1 1 1"/>
                  <geom size="0.005" pos="0.17 -0.02 -0.041" rgba="0.4 1 1 1"/>
                </body>
              </body>
            </body>
          </body>
        </body>
      </body>
      <body name="right_hip_yaw_link" pos="0 -0.0875 -0.1632" gravcomp="0">
        <inertial pos="0 0.026197 0.006647" quat="0.705013 0.0548434 -0.0553755 0.704899" mass="2.829" diaginertia="0.00574303 0.00455361 0.00349461"/>
        <joint name="right_hip_yaw_joint" pos="0 0 0" axis="0 0 1" range="-0.43 0.43"/>
        <geom type="mesh" contype="0" conaffinity="0" group="1" density="0" rgba="0.4 1 1 1" mesh="right_hip_yaw_link"/>
        <geom size="0.01 0.01" pos="0.02 0 0" quat="0.707107 0 0.707107 0" type="cylinder" rgba="0.4 1 1 1"/>
        <body name="right_hip_pitch_link" pos="0 -0.0755 0" quat="0.99875 0 -0.0499792 0" gravcomp="0">
          <inertial pos="-0.00781 0.004724 -6.3e-05" quat="0.711394 0.701575 -0.0249149 -0.0330266" mass="2.92" diaginertia="0.00560661 0.00445055 0.00385068"/>
          <joint name="right_hip_pitch_joint" pos="0 0 0" axis="0 1 0" range="-1.8 1.7"/>
          <geom type="mesh" contype="0" conaffinity="0" group="1" density="0" rgba="0.4 1 1 1" mesh="right_hip_pitch_link"/>
          <geom size="0.02 0.01" pos="0 -0.06 0" quat="0.707388 0.706825 0 0" type="cylinder" rgba="0.4 1 1 1"/>
          <body name="right_hip_roll_link" pos="0 0 0" gravcomp="0">
            <inertial pos="0.004171 0.008576 -0.194509" quat="0.772469 0.0074063 0.0146079 0.634842" mass="4.962" diaginertia="0.0480229 0.0462788 0.00887409"/>
            <joint name="right_hip_roll_joint" pos="0 0 0" axis="1 0 0" range="-3.14 0.43"/>
            <geom type="mesh" contype="0" conaffinity="0" group="1" density="0" rgba="0.4 1 1 1" mesh="right_hip_roll_link"/>
            <geom size="0.02 0.1" pos="0 0 -0.2" type="cylinder" rgba="0.4 1 1 1"/>
            <body name="right_knee_link" pos="0 0 -0.4" quat="0.995004 0 0.0998334 0" gravcomp="0">
              <inertial pos="0.000179 -0.000121 -0.168936" quat="0.909021 0.00514003 0.0104983 0.416585" mass="3.839" diaginertia="0.0391044 0.038959 0.00501125"/>
              <joint name="right_knee_joint" pos="0 0 0" axis="0 1 0" range="-0.32 1.99"/>
              <geom type="mesh" contype="0" conaffinity="0" group="1" density="0" rgba="0.4 1 1 1" mesh="right_knee_link"/>
              <geom size="0.02 0.1" pos="0 0 -0.2" type="cylinder" rgba="0.4 1 1 1"/>
              <body name="right_ankle_pitch_link" pos="0 0 -0.4" quat="0.99875 0 -0.0499792 0" gravcomp="0">
                <inertial pos="-0.000294 0 -0.010794" quat="0.999984 0 -0.00574445 0" mass="0.102" diaginertia="2.39454e-05 2.1837e-05 1.34126e-05"/>
                <joint name="right_ankle_pitch_joint" pos="0 0 0" axis="0 1 0" range="-0.797334 0.623598"/>
                <geom type="mesh" contype="0" conaffinity="0" group="1" density="0" rgba="0.4 1 1 1" mesh="right_ankle_pitch_link"/>
                <geom type="mesh" rgba="0.4 1 1 1" mesh="right_ankle_pitch_link"/>
                <body name="right_ankle_roll_link" pos="0 0 -0.02" gravcomp="0">
                  <inertial pos="0.029589 0 -0.015973" quat="0 0.725858 0 0.687845" mass="0.747" diaginertia="0.00359178 0.00343534 0.000640307"/>
                  <joint name="right_ankle_roll_joint" pos="0 0 0" axis="1 0 0" range="-0.261799 0.261799"/>
                  <geom type="mesh" contype="0" conaffinity="15" group="1" density="0" rgba="0.4 1 1 1" mesh="right_ankle_roll_link"/>
                  <geom size="0.005" pos="-0.08 0.038 -0.041" rgba="0.4 1 1 1"/>
                  <geom size="0.005" pos="-0.08 -0.038 -0.041" rgba="0.4 1 1 1"/>
                  <geom size="0.005" pos="-0.06 0.038 -0.041" rgba="0.4 1 1 1"/>
                  <geom size="0.005" pos="-0.06 -0.038 -0.041" rgba="0.4 1 1 1"/>
                  <geom size="0.005" pos="0.135 0.038 -0.041" rgba="0.4 1 1 1"/>
                  <geom size="0.005" pos="0.135 -0.038 -0.041" rgba="0.4 1 1 1"/>
                  <geom size="0.005" pos="0.095 0.038 -0.041" rgba="0.4 1 1 1"/>
                  <geom size="0.005" pos="0.095 -0.038 -0.041" rgba="0.4 1 1 1"/>
                  <geom size="0.005" pos="0.17 0.02 -0.041" rgba="0.4 1 1 1"/>
                  <geom size="0.005" pos="0.17 -0.02 -0.041" rgba="0.4 1 1 1"/>
                </body>
              </body>
            </body>
          </body>
        </body>
      </body>
      <site name="imu" size="0.01" pos="-0.04452 -0.01891 0.27756"/>
    </body>

  </worldbody>
  <actuator>
    <motor name="left_hip_yaw_joint" joint="left_hip_yaw_joint" gear="1" ctrllimited="true" ctrlrange="-200 200"/>
    <motor name="left_hip_pitch_joint" joint="left_hip_pitch_joint" gear="1" ctrllimited="true" ctrlrange="-200 200"/>
    <motor name="left_hip_roll_joint" joint="left_hip_roll_joint" gear="1" ctrllimited="true" ctrlrange="-200 200"/>
    <motor name="left_knee_joint" joint="left_knee_joint" gear="1" ctrllimited="true" ctrlrange="-200 200"/>
    <motor name="left_ankle_pitch_joint" joint="left_ankle_pitch_joint" gear="1" ctrllimited="true" ctrlrange="-200 200"/>
    <motor name="left_ankle_roll_joint" joint="left_ankle_roll_joint" gear="1" ctrllimited="true" ctrlrange="-200 200"/>
    <motor name="right_hip_yaw_joint" joint="right_hip_yaw_joint" gear="1" ctrllimited="true" ctrlrange="-200 200"/>
    <motor name="right_hip_pitch_joint" joint="right_hip_pitch_joint" gear="1" ctrllimited="true" ctrlrange="-200 200"/>
    <motor name="right_hip_roll_joint" joint="right_hip_roll_joint" gear="1" ctrllimited="true" ctrlrange="-200 200"/>
    <motor name="right_knee_joint" joint="right_knee_joint" gear="1" ctrllimited="true" ctrlrange="-200 200"/>
    <motor name="right_ankle_pitch_joint" joint="right_ankle_pitch_joint" gear="1" ctrllimited="true" ctrlrange="-200 200"/>
    <motor name="right_ankle_roll_joint" joint="right_ankle_roll_joint" gear="1" ctrllimited="true" ctrlrange="-200 200"/>
  </actuator>

  <sensor>
    <!-- Position sensors -->
    <actuatorpos name="right_hip_yaw_joint_p" actuator="right_hip_yaw_joint" user="13"/>
    <actuatorpos name="right_hip_pitch_joint_p" actuator="right_hip_pitch_joint" user="13"/>
    <actuatorpos name="right_hip_roll_joint_p" actuator="right_hip_roll_joint" user="13"/>
    <actuatorpos name="right_knee_joint_p" actuator="right_knee_joint" user="13"/>
    <actuatorpos name="right_ankle_pitch_joint_p" actuator="right_ankle_pitch_joint" user="13"/>
    <actuatorpos name="right_ankle_roll_joint_p" actuator="right_ankle_roll_joint" user="13"/>
    <actuatorpos name="left_hip_yaw_joint_p" actuator="left_hip_yaw_joint" user="13"/>
    <actuatorpos name="left_hip_pitch_joint_p" actuator="left_hip_pitch_joint" user="13"/>
    <actuatorpos name="left_hip_roll_joint_p" actuator="left_hip_roll_joint" user="13"/>
    <actuatorpos name="left_knee_joint_p" actuator="left_knee_joint" user="13"/>
    <actuatorpos name="left_ankle_pitch_joint_p" actuator="left_ankle_pitch_joint" user="13"/>
    <actuatorpos name="left_ankle_roll_joint_p" actuator="left_ankle_roll_joint" user="13"/>

    <!-- Velocity sensors -->
    <actuatorvel name="right_hip_yaw_joint_v" actuator="right_hip_yaw_joint" user="13" noise="1e-3"/>
    <actuatorvel name="right_hip_pitch_joint_v" actuator="right_hip_pitch_joint" user="13" noise="1e-3"/>
    <actuatorvel name="right_hip_roll_joint_v" actuator="right_hip_roll_joint" user="13" noise="1e-3"/>
    <actuatorvel name="right_knee_joint_v" actuator="right_knee_joint" user="13" noise="1e-3"/>
    <actuatorvel name="right_ankle_pitch_joint_v" actuator="right_ankle_pitch_joint" user="13" noise="1e-3"/>
    <actuatorvel name="right_ankle_roll_joint_v" actuator="right_ankle_roll_joint" user="13" noise="1e-3"/>
    <actuatorvel name="left_hip_yaw_joint_v" actuator="left_hip_yaw_joint" user="13" noise="1e-3"/>
    <actuatorvel name="left_hip_pitch_joint_v" actuator="left_hip_pitch_joint" user="13" noise="1e-3"/>
    <actuatorvel name="left_hip_roll_joint_v" actuator="left_hip_roll_joint" user="13" noise="1e-3"/>
    <actuatorvel name="left_knee_joint_v" actuator="left_knee_joint" user="13" noise="1e-3"/>
    <actuatorvel name="left_ankle_pitch_joint_v" actuator="left_ankle_pitch_joint" user="13" noise="1e-3"/>
    <actuatorvel name="left_ankle_roll_joint_v" actuator="left_ankle_roll_joint" user="13" noise="1e-3"/>

    <!-- Force sensors -->
    <actuatorfrc name="right_hip_yaw_joint_f" actuator="right_hip_yaw_joint" user="13" noise="1e-3"/>
    <actuatorfrc name="right_hip_pitch_joint_f" actuator="right_hip_pitch_joint" user="13" noise="1e-3"/>
    <actuatorfrc name="right_hip_roll_joint_f" actuator="right_hip_roll_joint" user="13" noise="1e-3"/>
    <actuatorfrc name="right_knee_joint_f" actuator="right_knee_joint" user="13" noise="1e-3"/>
    <actuatorfrc name="right_ankle_pitch_joint_f" actuator="right_ankle_pitch_joint" user="13" noise="1e-3"/>
    <actuatorfrc name="right_ankle_roll_joint_f" actuator="right_ankle_roll_joint" user="13" noise="1e-3"/>
    <actuatorfrc name="left_hip_yaw_joint_f" actuator="left_hip_yaw_joint" user="13" noise="1e-3"/>
    <actuatorfrc name="left_hip_pitch_joint_f" actuator="left_hip_pitch_joint" user="13" noise="1e-3"/>
    <actuatorfrc name="left_hip_roll_joint_f" actuator="left_hip_roll_joint" user="13" noise="1e-3"/>
    <actuatorfrc name="left_knee_joint_f" actuator="left_knee_joint" user="13" noise="1e-3"/>
    <actuatorfrc name="left_ankle_pitch_joint_f" actuator="left_ankle_pitch_joint" user="13" noise="1e-3"/>
    <actuatorfrc name="left_ankle_roll_joint_f" actuator="left_ankle_roll_joint" user="13" noise="1e-3"/>

    <framequat name='orientation' objtype='site' noise='0.001' objname='imu'/>
    <framepos name='position' objtype='site' noise='0.001' objname='imu'/>
    <gyro name='angular-velocity' site='imu' noise='0.005' cutoff='34.9'/>
    <velocimeter name='linear-velocity' site='imu' noise='0.001' cutoff='30'/>
    <accelerometer name='linear-acceleration' site='imu' noise='0.005' cutoff='157'/>
    <magnetometer name='magnetometer' site='imu'/>

  </sensor>
</mujoco>